Workbook
Name Slicer_Channel: #N/A
Name Slicer_Order_Status: #N/A
Name Slicer_Return_Rate: #N/A
Name Slicer_SKU_Name: #N/A

Sheet Rates 
A1: Channel | B1: Commision % | C1: Fixed Fee | D1: Forward Shipping | E1: Rev Shipping | F1: COD Flat Fee | G1: COD %
A2: Myntra | B2: 0.22 | C2: 70 | D2: 70 | E2: 70 | F2: 35 | G2: 0.02
A3: Meesho | B3: 0.12 | C3: 40 | D3: 60 | E3: 60 | F3: 35 | G3: 0.02
A4: Own Website | B4: 0.02 | C4: 0 | D4: 75 | E4: 75 | F4: 0 | G4: 0

Sheet SKUs
A1: SKU ID | B1: SKU Name | C1: Selling Price | D1: Product Cost | E1: Packaging
A2: SKU001 | B2: Basic Cotton Kurta | C2: 599 | D2: 210 | E2: 20
A3: SKU002 | B3: Printed Kurta | C3: 799 | D3: 280 | E3: 25
A4: SKU003 | B4: Embroidered Kurta | C4: 999 | D4: 350 | E4: 30
A5: SKU004 | B5: Designer Kurta | C5: 1299 | D5: 455 | E5: 40
A6: SKU005 | B6: Premium Silk Kurta | C6: 1899 | D6: 645 | E6: 45

Sheet Orders
A1: Order ID | B1: SKU ID | C1: SKU Name | D1: Channel | E1: Payment Type | F1: Order Status | G1: Selling Price | H1: Product Cost | I1: Packaging | J1: Commission% | K1: Fixed Fee | L1: Fwd Shipping | M1: Reverse Shipping | N1: COD Flat Fee | O1: COD% | P1: Platform Commission | Q1: GST on Fees | R1: COD Handling Fee | S1: Reverse Shipping Cost | T1: CM2
A2: ="ORD"&TEXT(ROW(A2)-1, "000") -> ORD001 | B2: SKU001 | C2: =VLOOKUP(B2,SKUs!$A$2:$E$6,2,FALSE) -> Basic Cotton Kurta | D2: Own Website | E2: Prepaid | F2: Delivered | G2: =VLOOKUP(Orders!B2,SKUs!$A$2:$D$6,3,FALSE) -> 599 | H2: =VLOOKUP(B2,SKUs!$A$2:$D$6,4,FALSE) -> 210 | I2: =VLOOKUP(B2,SKUs!$A$2:$E$6,5,FALSE) -> 20 | J2: =VLOOKUP(D2,'Rates '!$A$2:$G$4,2,FALSE) -> 0.02 | K2: =VLOOKUP(D2,'Rates '!$A$2:$G$4,3,FALSE) -> 0 | L2: =VLOOKUP(D2,'Rates '!$A$2:$G$4,4,FALSE) -> 75 | M2: =VLOOKUP(D2,'Rates '!$A$2:$G$4,5,FALSE) -> 75 | N2: =VLOOKUP(D2,'Rates '!$A$2:$G$4,6,FALSE) -> 0 | O2: =VLOOKUP(D2,'Rates '!$A$2:$G$4,7,FALSE) -> 0 | P2: =G2*J2 -> 11.98 | Q2: =(P2+K2)*0.18 -> 2.1564 | R2: =IF(E2="COD",N2+(O2*G2),0) -> 0 | S2: =IF(F2="Returned",M2,0) -> 0 | T2: =IF(F2="Delivered",(G2-I2-K2-L2-P2-Q2-R2-H2),-(L2+R2+I2+S2)) -> 279.8636
A3: ="ORD"&TEXT(ROW(A3)-1, "000") -> ORD002 | B3: SKU005 | C3: =VLOOKUP(B3,SKUs!$A$2:$E$6,2,FALSE) -> Premium Silk Kurta | D3: Own Website | E3: Prepaid | F3: Delivered | G3: =VLOOKUP(Orders!B3,SKUs!$A$2:$D$6,3,FALSE) -> 1899 | H3: =VLOOKUP(B3,SKUs!$A$2:$D$6,4,FALSE) -> 645 | I3: =VLOOKUP(B3,SKUs!$A$2:$E$6,5,FALSE) -> 45 | J3: =VLOOKUP(D3,'Rates '!$A$2:$G$4,2,FALSE) -> 0.02 | K3: =VLOOKUP(D3,'Rates '!$A$2:$G$4,3,FALSE) -> 0 | L3: =VLOOKUP(D3,'Rates '!$A$2:$G$4,4,FALSE) -> 75 | M3: =VLOOKUP(D3,'Rates '!$A$2:$G$4,5,FALSE) -> 75 | N3: =VLOOKUP(D3,'Rates '!$A$2:$G$4,6,FALSE) -> 0 | O3: =VLOOKUP(D3,'Rates '!$A$2:$G$4,7,FALSE) -> 0 | P3: =G3*J3 -> 37.98 | Q3: =(P3+K3)*0.18 -> 6.8364 | R3: =IF(E3="COD",N3+(O3*G3),0) -> 0 | S3: =IF(F3="Returned",M3,0) -> 0 | T3: =IF(F3="Delivered",(G3-I3-K3-L3-P3-Q3-R3-H3),-(L3+R3+I3+S3)) -> 1089.1836
A4: ="ORD"&TEXT(ROW(A4)-1, "000") -> ORD003 | B4: SKU003 | C4: =VLOOKUP(B4,SKUs!$A$2:$E$6,2,FALSE) -> Embroidered Kurta | D4: Meesho | E4: COD | F4: Delivered | G4: =VLOOKUP(Orders!B4,SKUs!$A$2:$D$6,3,FALSE) -> 999 | H4: =VLOOKUP(B4,SKUs!$A$2:$D$6,4,FALSE) -> 350 | I4: =VLOOKUP(B4,SKUs!$A$2:$E$6,5,FALSE) -> 30 | J4: =VLOOKUP(D4,'Rates '!$A$2:$G$4,2,FALSE) -> 0.12 | K4: =VLOOKUP(D4,'Rates '!$A$2:$G$4,3,FALSE) -> 40 | L4: =VLOOKUP(D4,'Rates '!$A$2:$G$4,4,FALSE) -> 60 | M4: =VLOOKUP(D4,'Rates '!$A$2:$G$4,5,FALSE) -> 60 | N4: =VLOOKUP(D4,'Rates '!$A$2:$G$4,6,FALSE) -> 35 | O4: =VLOOKUP(D4,'Rates '!$A$2:$G$4,7,FALSE) -> 0.02 | P4: =G4*J4 -> 119.88 | Q4: =(P4+K4)*0.18 -> 28.7784 | R4: =IF(E4="COD",N4+(O4*G4),0) -> 54.98 | S4: =IF(F4="Returned",M4,0) -> 0 | T4: =IF(F4="Delivered",(G4-I4-K4-L4-P4-Q4-R4-H4),-(L4+R4+I4+S4)) -> 315.3616
A5: ="ORD"&TEXT(ROW(A5)-1, "000") -> ORD004 | B5: SKU003 | C5: =VLOOKUP(B5,SKUs!$A$2:$E$6,2,FALSE) -> Embroidered Kurta | D5: Own Website | E5: Prepaid | F5: Delivered | G5: =VLOOKUP(Orders!B5,SKUs!$A$2:$D$6,3,FALSE) -> 999 | H5: =VLOOKUP(B5,SKUs!$A$2:$D$6,4,FALSE) -> 350 | I5: =VLOOKUP(B5,SKUs!$A$2:$E$6,5,FALSE) -> 30 | J5: =VLOOKUP(D5,'Rates '!$A$2:$G$4,2,FALSE) -> 0.02 | K5: =VLOOKUP(D5,'Rates '!$A$2:$G$4,3,FALSE) -> 0 | L5: =VLOOKUP(D5,'Rates '!$A$2:$G$4,4,FALSE) -> 75 | M5: =VLOOKUP(D5,'Rates '!$A$2:$G$4,5,FALSE) -> 75 | N5: =VLOOKUP(D5,'Rates '!$A$2:$G$4,6,FALSE) -> 0 | O5: =VLOOKUP(D5,'Rates '!$A$2:$G$4,7,FALSE) -> 0 | P5: =G5*J5 -> 19.98 | Q5: =(P5+K5)*0.18 -> 3.5964 | R5: =IF(E5="COD",N5+(O5*G5),0) -> 0 | S5: =IF(F5="Returned",M5,0) -> 0 | T5: =IF(F5="Delivered",(G5-I5-K5-L5-P5-Q5-R5-H5),-(L5+R5+I5+S5)) -> 520.4236
A6: ="ORD"&TEXT(ROW(A6)-1, "000") -> ORD005 | B6: SKU001 | C6: =VLOOKUP(B6,SKUs!$A$2:$E$6,2,FALSE) -> Basic Cotton Kurta | D6: Myntra | E6: Prepaid | F6: Delivered | G6: =VLOOKUP(Orders!B6,SKUs!$A$2:$D$6,3,FALSE) -> 599 | H6: =VLOOKUP(B6,SKUs!$A$2:$D$6,4,FALSE) -> 210 | I6: =VLOOKUP(B6,SKUs!$A$2:$E$6,5,FALSE) -> 20 | J6: =VLOOKUP(D6,'Rates '!$A$2:$G$4,2,FALSE) -> 0.22 | K6: =VLOOKUP(D6,'Rates '!$A$2:$G$4,3,FALSE) -> 70 | L6: =VLOOKUP(D6,'Rates '!$A$2:$G$4,4,FALSE) -> 70 | M6: =VLOOKUP(D6,'Rates '!$A$2:$G$4,5,FALSE) -> 70 | N6: =VLOOKUP(D6,'Rates '!$A$2:$G$4,6,FALSE) -> 35 | O6: =VLOOKUP(D6,'Rates '!$A$2:$G$4,7,FALSE) -> 0.02 | P6: =G6*J6 -> 131.78 | Q6: =(P6+K6)*0.18 -> 36.3204 | R6: =IF(E6="COD",N6+(O6*G6),0) -> 0 | S6: =IF(F6="Returned",M6,0) -> 0 | T6: =IF(F6="Delivered",(G6-I6-K6-L6-P6-Q6-R6-H6),-(L6+R6+I6+S6)) -> 60.8996
A7: ="ORD"&TEXT(ROW(A7)-1, "000") -> ORD006 | B7: SKU002 | C7: =VLOOKUP(B7,SKUs!$A$2:$E$6,2,FALSE) -> Printed Kurta | D7: Meesho | E7: Prepaid | F7: Returned | G7: =VLOOKUP(Orders!B7,SKUs!$A$2:$D$6,3,FALSE) -> 799 | H7: =VLOOKUP(B7,SKUs!$A$2:$D$6,4,FALSE) -> 280 | I7: =VLOOKUP(B7,SKUs!$A$2:$E$6,5,FALSE) -> 25 | J7: =VLOOKUP(D7,'Rates '!$A$2:$G$4,2,FALSE) -> 0.12 | K7: =VLOOKUP(D7,'Rates '!$A$2:$G$4,3,FALSE) -> 40 | L7: =VLOOKUP(D7,'Rates '!$A$2:$G$4,4,FALSE) -> 60 | M7: =VLOOKUP(D7,'Rates '!$A$2:$G$4,5,FALSE) -> 60 | N7: =VLOOKUP(D7,'Rates '!$A$2:$G$4,6,FALSE) -> 35 | O7: =VLOOKUP(D7,'Rates '!$A$2:$G$4,7,FALSE) -> 0.02 | P7: =G7*J7 -> 95.88 | Q7: =(P7+K7)*0.18 -> 24.4584 | R7: =IF(E7="COD",N7+(O7*G7),0) -> 0 | S7: =IF(F7="Returned",M7,0) -> 60 | T7: =IF(F7="Delivered",(G7-I7-K7-L7-P7-Q7-R7-H7),-(L7+R7+I7+S7)) -> -145
A8: ="ORD"&TEXT(ROW(A8)-1, "000") -> ORD007 | B8: SKU001 | C8: =VLOOKUP(B8,SKUs!$A$2:$E$6,2,FALSE) -> Basic Cotton Kurta | D8: Myntra | E8: Prepaid | F8: Delivered | G8: =VLOOKUP(Orders!B8,SKUs!$A$2:$D$6,3,FALSE) -> 599 | H8: =VLOOKUP(B8,SKUs!$A$2:$D$6,4,FALSE) -> 210 | I8: =VLOOKUP(B8,SKUs!$A$2:$E$6,5,FALSE) -> 20 | J8: =VLOOKUP(D8,'Rates '!$A$2:$G$4,2,FALSE) -> 0.22 | K8: =VLOOKUP(D8,'Rates '!$A$2:$G$4,3,FALSE) -> 70 | L8: =VLOOKUP(D8,'Rates '!$A$2:$G$4,4,FALSE) -> 70 | M8: =VLOOKUP(D8,'Rates '!$A$2:$G$4,5,FALSE) -> 70 | N8: =VLOOKUP(D8,'Rates '!$A$2:$G$4,6,FALSE) -> 35 | O8: =VLOOKUP(D8,'Rates '!$A$2:$G$4,7,FALSE) -> 0.02 | P8: =G8*J8 -> 131.78 | Q8: =(P8+K8)*0.18 -> 36.3204 | R8: =IF(E8="COD",N8+(O8*G8),0) -> 0 | S8: =IF(F8="Returned",M8,0) -> 0 | T8: =IF(F8="Delivered",(G8-I8-K8-L8-P8-Q8-R8-H8),-(L8+R8+I8+S8)) -> 60.8996
A9: ="ORD"&TEXT(ROW(A9)-1, "000") -> ORD008 | B9: SKU002 | C9: =VLOOKUP(B9,SKUs!$A$2:$E$6,2,FALSE) -> Printed Kurta | D9: Meesho | E9: Prepaid | F9: Delivered | G9: =VLOOKUP(Orders!B9,SKUs!$A$2:$D$6,3,FALSE) -> 799 | H9: =VLOOKUP(B9,SKUs!$A$2:$D$6,4,FALSE) -> 280 | I9: =VLOOKUP(B9,SKUs!$A$2:$E$6,5,FALSE) -> 25 | J9: =VLOOKUP(D9,'Rates '!$A$2:$G$4,2,FALSE) -> 0.12 | K9: =VLOOKUP(D9,'Rates '!$A$2:$G$4,3,FALSE) -> 40 | L9: =VLOOKUP(D9,'Rates '!$A$2:$G$4,4,FALSE) -> 60 | M9: =VLOOKUP(D9,'Rates '!$A$2:$G$4,5,FALSE) -> 60 | N9: =VLOOKUP(D9,'Rates '!$A$2:$G$4,6,FALSE) -> 35 | O9: =VLOOKUP(D9,'Rates '!$A$2:$G$4,7,FALSE) -> 0.02 | P9: =G9*J9 -> 95.88 | Q9: =(P9+K9)*0.18 -> 24.4584 | R9: =IF(E9="COD",N9+(O9*G9),0) -> 0 | S9: =IF(F9="Returned",M9,0) -> 0 | T9: =IF(F9="Delivered",(G9-I9-K9-L9-P9-Q9-R9-H9),-(L9+R9+I9+S9)) -> 273.6616
A10: ="ORD"&TEXT(ROW(A10)-1, "000") -> ORD009 | B10: SKU002 | C10: =VLOOKUP(B10,SKUs!$A$2:$E$6,2,FALSE) -> Printed Kurta | D10: Meesho | E10: Prepaid | F10: Delivered | G10: =VLOOKUP(Orders!B10,SKUs!$A$2:$D$6,3,FALSE) -> 799 | H10: =VLOOKUP(B10,SKUs!$A$2:$D$6,4,FALSE) -> 280 | I10: =VLOOKUP(B10,SKUs!$A$2:$E$6,5,FALSE) -> 25 | J10: =VLOOKUP(D10,'Rates '!$A$2:$G$4,2,FALSE) -> 0.12 | K10: =VLOOKUP(D10,'Rates '!$A$2:$G$4,3,FALSE) -> 40 | L10: =VLOOKUP(D10,'Rates '!$A$2:$G$4,4,FALSE) -> 60 | M10: =VLOOKUP(D10,'Rates '!$A$2:$G$4,5,FALSE) -> 60 | N10: =VLOOKUP(D10,'Rates '!$A$2:$G$4,6,FALSE) -> 35 | O10: =VLOOKUP(D10,'Rates '!$A$2:$G$4,7,FALSE) -> 0.02 | P10: =G10*J10 -> 95.88 | Q10: =(P10+K10)*0.18 -> 24.4584 | R10: =IF(E10="COD",N10+(O10*G10),0) -> 0 | S10: =IF(F10="Returned",M10,0) -> 0 | T10: =IF(F10="Delivered",(G10-I10-K10-L10-P10-Q10-R10-H10),-(L10+R10+I10+S10)) -> 273.6616
A11: ="ORD"&TEXT(ROW(A11)-1, "000") -> ORD010 | B11: SKU003 | C11: =VLOOKUP(B11,SKUs!$A$2:$E$6,2,FALSE) -> Embroidered Kurta | D11: Meesho | E11: COD | F11: Returned | G11: =VLOOKUP(Orders!B11,SKUs!$A$2:$D$6,3,FALSE) -> 999 | H11: =VLOOKUP(B11,SKUs!$A$2:$D$6,4,FALSE) -> 350 | I11: =VLOOKUP(B11,SKUs!$A$2:$E$6,5,FALSE) -> 30 | J11: =VLOOKUP(D11,'Rates '!$A$2:$G$4,2,FALSE) -> 0.12 | K11: =VLOOKUP(D11,'Rates '!$A$2:$G$4,3,FALSE) -> 40 | L11: =VLOOKUP(D11,'Rates '!$A$2:$G$4,4,FALSE) -> 60 | M11: =VLOOKUP(D11,'Rates '!$A$2:$G$4,5,FALSE) -> 60 | N11: =VLOOKUP(D11,'Rates '!$A$2:$G$4,6,FALSE) -> 35 | O11: =VLOOKUP(D11,'Rates '!$A$2:$G$4,7,FALSE) -> 0.02 | P11: =G11*J11 -> 119.88 | Q11: =(P11+K11)*0.18 -> 28.7784 | R11: =IF(E11="COD",N11+(O11*G11),0) -> 54.98 | S11: =IF(F11="Returned",M11,0) -> 60 | T11: =IF(F11="Delivered",(G11-I11-K11-L11-P11-Q11-R11-H11),-(L11+R11+I11+S11)) -> -204.98
A12: ="ORD"&TEXT(ROW(A12)-1, "000") -> ORD011 | B12: SKU001 | C12: =VLOOKUP(B12,SKUs!$A$2:$E$6,2,FALSE) -> Basic Cotton Kurta | D12: Myntra | E12: Prepaid | F12: Delivered | G12: =VLOOKUP(Orders!B12,SKUs!$A$2:$D$6,3,FALSE) -> 599 | H12: =VLOOKUP(B12,SKUs!$A$2:$D$6,4,FALSE) -> 210 | I12: =VLOOKUP(B12,SKUs!$A$2:$E$6,5,FALSE) -> 20 | J12: =VLOOKUP(D12,'Rates '!$A$2:$G$4,2,FALSE) -> 0.22 | K12: =VLOOKUP(D12,'Rates '!$A$2:$G$4,3,FALSE) -> 70 | L12: =VLOOKUP(D12,'Rates '!$A$2:$G$4,4,FALSE) -> 70 | M12: =VLOOKUP(D12,'Rates '!$A$2:$G$4,5,FALSE) -> 70 | N12: =VLOOKUP(D12,'Rates '!$A$2:$G$4,6,FALSE) -> 35 | O12: =VLOOKUP(D12,'Rates '!$A$2:$G$4,7,FALSE) -> 0.02 | P12: =G12*J12 -> 131.78 | Q12: =(P12+K12)*0.18 -> 36.3204 | R12: =IF(E12="COD",N12+(O12*G12),0) -> 0 | S12: =IF(F12="Returned",M12,0) -> 0 | T12: =IF(F12="Delivered",(G12-I12-K12-L12-P12-Q12-R12-H12),-(L12+R12+I12+S12)) -> 60.8996
A13: ="ORD"&TEXT(ROW(A13)-1, "000") -> ORD012 | B13: SKU004 | C13: =VLOOKUP(B13,SKUs!$A$2:$E$6,2,FALSE) -> Designer Kurta | D13: Meesho | E13: COD | F13: Returned | G13: =VLOOKUP(Orders!B13,SKUs!$A$2:$D$6,3,FALSE) -> 1299 | H13: =VLOOKUP(B13,SKUs!$A$2:$D$6,4,FALSE) -> 455 | I13: =VLOOKUP(B13,SKUs!$A$2:$E$6,5,FALSE) -> 40 | J13: =VLOOKUP(D13,'Rates '!$A$2:$G$4,2,FALSE) -> 0.12 | K13: =VLOOKUP(D13,'Rates '!$A$2:$G$4,3,FALSE) -> 40 | L13: =VLOOKUP(D13,'Rates '!$A$2:$G$4,4,FALSE) -> 60 | M13: =VLOOKUP(D13,'Rates '!$A$2:$G$4,5,FALSE) -> 60 | N13: =VLOOKUP(D13,'Rates '!$A$2:$G$4,6,FALSE) -> 35 | O13: =VLOOKUP(D13,'Rates '!$A$2:$G$4,7,FALSE) -> 0.02 | P13: =G13*J13 -> 155.88 | Q13: =(P13+K13)*0.18 -> 35.2584 | R13: =IF(E13="COD",N13+(O13*G13),0) -> 60.98 | S13: =IF(F13="Returned",M13,0) -> 60 | T13: =IF(F13="Delivered",(G13-I13-K13-L13-P13-Q13-R13-H13),-(L13+R13+I13+S13)) -> -220.98
... A101: ="ORD"&TEXT(ROW(A101)-1, "000") -> ORD100 | B101: SKU004 | C101: =VLOOKUP(B101,SKUs!$A$2:$E$6,2,FALSE) -> Designer Kurta | D101: Own Website | E101: Prepaid | F101: Returned | G101: =VLOOKUP(Orders!B101,SKUs!$A$2:$D$6,3,FALSE) -> 1299 | H101: =VLOOKUP(B101,SKUs!$A$2:$D$6,4,FALSE) -> 455 | I101: =VLOOKUP(B101,SKUs!$A$2:$E$6,5,FALSE) -> 40 | J101: =VLOOKUP(D101,'Rates '!$A$2:$G$4,2,FALSE) -> 0.02 | K101: =VLOOKUP(D101,'Rates '!$A$2:$G$4,3,FALSE) -> 0 | L101: =VLOOKUP(D101,'Rates '!$A$2:$G$4,4,FALSE) -> 75 | M101: =VLOOKUP(D101,'Rates '!$A$2:$G$4,5,FALSE) -> 75 | N101: =VLOOKUP(D101,'Rates '!$A$2:$G$4,6,FALSE) -> 0 | O101: =VLOOKUP(D101,'Rates '!$A$2:$G$4,7,FALSE) -> 0 | P101: =G101*J101 -> 25.98 | Q101: =(P101+K101)*0.18 -> 4.6764 | R101: =IF(E101="COD",N101+(O101*G101),0) -> 0 | S101: =IF(F101="Returned",M101,0) -> 75 | T101: =IF(F101="Delivered",(G101-I101-K101-L101-P101-Q101-R101-H101),-(L101+R101+I101+S101)) -> -190

Sheet Summary
A1: Profitability by SKU
A2: Row Labels | B2: Sum of CM2
A3: Basic Cotton Kurta | B3: 373.1504
A4: Printed Kurta | B4: 715.1916
A5: Embroidered Kurta | B5: 4987.1088
A6: Designer Kurta | B6: 5545.2432
A7: Premium Silk Kurta | B7: 10200.926
A8: Grand Total | B8: 21821.62
A13: Profitability by Channel
A14: Row Labels | B14: Average CM2 per order
A15: Meesho | B15: 242.49667
A16: Myntra | B16: 78.729112
A17: Own Website | B17: 330.38776
A18: Grand Total | B18: 218.2162
A23: Cost of Returns
A24: Row Labels | B24: Sum of CM2 | C24: Count of Order ID
A25: Delivered | B25: 28597.34 | C25: 65
A26: Returned | B26: -6775.72 | C26: 35
A27: Grand Total | B27: 21821.62 | C27: 100
A32: Return Rate by SKU
A33: Count of Order ID | B33: Column Labels
A34: Row Labels | B34: Delivered | C34: Returned | D34: Grand Total
A35: Basic Cotton Kurta | B35: 9 | C35: 5 | D35: 14
A36: Designer Kurta | B36: 12 | C36: 3 | D36: 15
A37: Embroidered Kurta | B37: 18 | C37: 7 | D37: 25
A38: Printed Kurta | B38: 11 | C38: 9 | D38: 20
A39: Premium Silk Kurta | B39: 15 | C39: 11 | D39: 26
A40: Grand Total | B40: 65 | C40: 35 | D40: 100
E43: Scenario Summary
E44: Label | F44: Formula Value
E45: Avg CM2 - Delivered | F45: =AVERAGEIF(Orders!F:F, "Delivered", Orders!T:T) -> 439.95908
E46: Avg CM2 - Returned | F46: =AVERAGEIF(Orders!F:F, "Returned", Orders!T:T) -> -193.592
E47: Total Orders | F47: 100
E48: Return Rate Assumption | F48: 0.3
E49: Projected Total CM2 | F49: =(1-F48)*F47*F45+(F48*F47*F46) -> 24989.375
E52: Status | F52: CM2
E53: Delivered | F53: =GETPIVOTDATA("Sum of CM2",$A$24,"Order Status","Delivered") -> 28597.34
E54: Returned | F54: =GETPIVOTDATA("Sum of CM2",$A$24,"Order Status","Returned") -> -6775.72
E56: Return Rate by SKU
E57: SKU | F57: Return Rate
...

Sheet Scenario Summary
B2: Scenario Summary
D3: Actual Dataset (35%): | E3: Base Case (30% Returns) | F3: Optimistic (20% Returns) | G3: Pessimistic (40% Returns) | H3: Best Case (10%)
B4: Changing Cells:
C5: $F$48 | D5: 0.35 | E5: 0.3 | F5: 0.2 | G5: 0.4 | H5: 0.1
B6: Result Cells:
C7: $F$49 | D7: 24989.375 | E7: 24989.375 | F7: 31324.886 | G7: 18653.865 | H7: 37660.397

Sheet Dashboard
A1: Indian D2C True Profitability Dashboard Fashion Category | 100 Orders Simulated | Indian D2C Model | FY 2025-2026
B5: TOTAL ORDERS | J5: TOTAL CM2 (₹) | R5: CM2 LOST TO RETURNS (₹) | Z5: AVG CM2 PER ORDER (₹) | AH5: RETURN RATE
B8: =Summary!C8 -> 0 | J8: =Summary!B8 -> 21821.62 | R8: =Summary!B26 -> -6775.72 | Z8: =Summary!B15 -> 242.49667 | AH8: =Summary!C40/100 -> 0.35
